<?xml version="1.0" ?>
<!-- =================================================================================== -->
<!-- |    This document was autogenerated by xacro from indy7.xacro                    | -->
<!-- |    EDITING THIS FILE BY HAND IS NOT RECOMMENDED                                 | -->
<!-- =================================================================================== -->
<robot name="humanoid" xmlns:xacro="http://ros.org/wiki/xacro">
	<!-- <material name="grey"> <color rgba="0.5 0.5 0.5 1"/> </material> -->
	<link name="body_link">
		<visual>
			<origin rpy="0 0 0" xyz="0 0 0"/>
			<geometry>
				<mesh filename="meshes/body.stl"/>
			</geometry>
			<material name="metal_grey"/>
		</visual>
		<collision>
			<origin rpy="0 0 0" xyz="0 0 0"/>
			<geometry>
				<mesh filename="meshes/body.stl" />
			</geometry>
		</collision>
		<inertial>
		<origin rpy="0 0 0" xyz="0 0 0"/>
			<mass value="1.59306955"/>
			<inertia ixx="+0.00572623" ixy="+0.00000251" ixz="-0.00011380" iyy="+0.00558959" iyz="-0.00000014" izz="+0.00966674"/>
		</inertial>
	</link>
	<link name="left_yaw_link">
		<visual>
			<origin rpy="0 0 0" xyz="0 0 0"/>
			<geometry>
				<mesh filename="meshes/yaw_link.stl"/>
			</geometry>
			<material name="metal_grey"/>
		</visual>
		<collision>
			<origin rpy="0 0 0" xyz="0 0 0"/>
			<geometry>
				<mesh filename="meshes/yaw_link.stl" />
			</geometry>
		</collision>
		<inertial>
		<origin rpy="0 0 0" xyz="0 0 0"/>
			<mass value="1.59306955"/>
			<inertia ixx="+0.00572623" ixy="+0.00000251" ixz="-0.00011380" iyy="+0.00558959" iyz="-0.00000014" izz="+0.00966674"/>
		</inertial>
	</link>
	<link name="right_yaw_link">
		<visual>
			<origin rpy="0 0 0" xyz="0 0 0"/>
			<geometry>
				<mesh filename="meshes/yaw_link.stl"/>
			</geometry>
			<material name="metal_grey"/>
		</visual>
		<collision>
			<origin rpy="0 0 0" xyz="0 0 0"/>
			<geometry>
				<mesh filename="meshes/yaw_link.stl" />
			</geometry>
		</collision>
		<inertial>
		<origin rpy="0 0 0" xyz="0 0 0"/>
			<mass value="1.59306955"/>
			<inertia ixx="+0.00572623" ixy="+0.00000251" ixz="-0.00011380" iyy="+0.00558959" iyz="-0.00000014" izz="+0.00966674"/>
		</inertial>
	</link>
	<link name="left_roll_link">
		<visual>
			<origin rpy="0 0 0" xyz="0 0 0"/>
			<geometry>
				<mesh filename="meshes/roll_link.stl"/>
			</geometry>
			<material name="metal_grey"/>
		</visual>
		<collision>
			<origin rpy="0 0 0" xyz="0 0 0"/>
			<geometry>
				<mesh filename="meshes/roll_link.stl" />
			</geometry>
		</collision>
		<inertial>
		<origin rpy="0 0 0" xyz="0 0 0"/>
			<mass value="1.59306955"/>
			<inertia ixx="+0.00572623" ixy="+0.00000251" ixz="-0.00011380" iyy="+0.00558959" iyz="-0.00000014" izz="+0.00966674"/>
		</inertial>
	</link>
	<link name="right_roll_link">
		<visual>
			<origin rpy="0 0 0" xyz="0 0 0"/>
			<geometry>
				<mesh filename="meshes/roll_link.stl"/>
			</geometry>
			<material name="metal_grey"/>
		</visual>
		<collision>
			<origin rpy="0 0 0" xyz="0 0 0"/>
			<geometry>
				<mesh filename="meshes/roll_link.stl" />
			</geometry>
		</collision>
		<inertial>
		<origin rpy="0 0 0" xyz="0 0 0"/>
			<mass value="1.59306955"/>
			<inertia ixx="+0.00572623" ixy="+0.00000251" ixz="-0.00011380" iyy="+0.00558959" iyz="-0.00000014" izz="+0.00966674"/>
		</inertial>
	</link>
	<link name="left_pitch_link">
		<visual>
			<origin rpy="0 0 0" xyz="0 0 0"/>
			<geometry>
				<mesh filename="meshes/pitch_link.stl"/>
			</geometry>
			<material name="metal_grey"/>
		</visual>
		<collision>
			<origin rpy="0 0 0" xyz="0 0 0"/>
			<geometry>
				<mesh filename="meshes/pitch_link.stl" />
			</geometry>
		</collision>
		<inertial>
		<origin rpy="0 0 0" xyz="0 0 0"/>
			<mass value="1.59306955"/>
			<inertia ixx="+0.00572623" ixy="+0.00000251" ixz="-0.00011380" iyy="+0.00558959" iyz="-0.00000014" izz="+0.00966674"/>
		</inertial>
	</link>
	<link name="right_pitch_link">
		<visual>
			<origin rpy="0 0 0" xyz="0 0 0"/>
			<geometry>
				<mesh filename="meshes/pitch_link.stl"/>
			</geometry>
			<material name="metal_grey"/>
		</visual>
		<collision>
			<origin rpy="0 0 0" xyz="0 0 0"/>
			<geometry>
				<mesh filename="meshes/pitch_link.stl" />
			</geometry>
		</collision>
		<inertial>
		<origin rpy="0 0 0" xyz="0 0 0"/>
			<mass value="1.59306955"/>
			<inertia ixx="+0.00572623" ixy="+0.00000251" ixz="-0.00011380" iyy="+0.00558959" iyz="-0.00000014" izz="+0.00966674"/>
		</inertial>
	</link>
	<link name="left_leg_link">
		<visual>
			<origin rpy="0 0 0" xyz="0 0 0"/>
			<geometry>
				<mesh filename="meshes/leg_link.stl"/>
			</geometry>
			<material name="metal_grey"/>
		</visual>
		<collision>
			<origin rpy="0 0 0" xyz="0 0 0"/>
			<geometry>
				<mesh filename="meshes/leg_link.stl" />
			</geometry>
		</collision>
		<inertial>
		<origin rpy="0 0 0" xyz="0 0 0"/>
			<mass value="1.59306955"/>
			<inertia ixx="+0.00572623" ixy="+0.00000251" ixz="-0.00011380" iyy="+0.00558959" iyz="-0.00000014" izz="+0.00966674"/>
		</inertial>
	</link>
	<link name="right_leg_link">
		<visual>
			<origin rpy="0 0 0" xyz="0 0 0"/>
			<geometry>
				<mesh filename="meshes/leg_link.stl"/>
			</geometry>
			<material name="metal_grey"/>
		</visual>
		<collision>
			<origin rpy="0 0 0" xyz="0 0 0"/>
			<geometry>
				<mesh filename="meshes/leg_link.stl" />
			</geometry>
		</collision>
		<inertial>
		<origin rpy="0 0 0" xyz="0 0 0"/>
			<mass value="1.59306955"/>
			<inertia ixx="+0.00572623" ixy="+0.00000251" ixz="-0.00011380" iyy="+0.00558959" iyz="-0.00000014" izz="+0.00966674"/>
		</inertial>
	</link>
	<link name="left_leg_link2">
		<visual>
			<origin rpy="0 0 0" xyz="0 0 0"/>
			<geometry>
				<mesh filename="meshes/leg_link2.stl"/>
			</geometry>
			<material name="metal_grey"/>
		</visual>
		<collision>
			<origin rpy="0 0 0" xyz="0 0 0"/>
			<geometry>
				<mesh filename="meshes/leg_link2.stl" />
			</geometry>
		</collision>
		<inertial>
		<origin rpy="0 0 0" xyz="0 0 0"/>
			<mass value="1.59306955"/>
			<inertia ixx="+0.00572623" ixy="+0.00000251" ixz="-0.00011380" iyy="+0.00558959" iyz="-0.00000014" izz="+0.00966674"/>
		</inertial>
	</link>	
	<link name="right_leg_link2">
		<visual>
			<origin rpy="0 0 0" xyz="0 0 0"/>
			<geometry>
				<mesh filename="meshes/leg_link2.stl"/>
			</geometry>
			<material name="metal_grey"/>
		</visual>
		<collision>
			<origin rpy="0 0 0" xyz="0 0 0"/>
			<geometry>
				<mesh filename="meshes/leg_link2.stl" />
			</geometry>
		</collision>
		<inertial>
		<origin rpy="0 0 0" xyz="0 0 0"/>
			<mass value="1.59306955"/>
			<inertia ixx="+0.00572623" ixy="+0.00000251" ixz="-0.00011380" iyy="+0.00558959" iyz="-0.00000014" izz="+0.00966674"/>
		</inertial>
	</link>	
	<link name="left_feet_link">
		<visual>
			<origin rpy="0 0 0" xyz="0 0 0"/>
			<geometry>
				<mesh filename="meshes/feet_link.stl"/>
			</geometry>
			<material name="metal_grey"/>
		</visual>
		<collision>
			<origin rpy="0 0 0" xyz="0 0 0"/>
			<geometry>
				<mesh filename="meshes/feet_link.stl" />
			</geometry>
		</collision>
		<inertial>
		<origin rpy="0 0 0" xyz="0 0 0"/>
			<mass value="1.59306955"/>
			<inertia ixx="+0.00572623" ixy="+0.00000251" ixz="-0.00011380" iyy="+0.00558959" iyz="-0.00000014" izz="+0.00966674"/>
		</inertial>
	</link>
	<link name="right_feet_link">
		<visual>
			<origin rpy="0 0 0" xyz="0 0 0"/>
			<geometry>
				<mesh filename="meshes/feet_link.stl"/>
			</geometry>
			<material name="metal_grey"/>
		</visual>
		<collision>
			<origin rpy="0 0 0" xyz="0 0 0"/>
			<geometry>
				<mesh filename="meshes/feet_link.stl" />
			</geometry>
		</collision>
		<inertial>
		<origin rpy="0 0 0" xyz="0 0 0"/>
			<mass value="1.59306955"/>
			<inertia ixx="+0.00572623" ixy="+0.00000251" ixz="-0.00011380" iyy="+0.00558959" iyz="-0.00000014" izz="+0.00966674"/>
		</inertial>
	</link>




	<joint name="left_yaw_joint" type="revolute">
		<parent link="body_link"/>
		<child link="left_yaw_link"/>
		<origin rpy="0 0 0" xyz="0.0519 0 -0.021003"/>
		<axis xyz="0 0 1"/>
		<limit effort="10" lower="-3.141592" upper="3.141592" velocity="1"/>
	</joint>

	<joint name="right_yaw_joint" type="revolute">
		<parent link="body_link"/>
		<child link="right_yaw_link"/>
		<origin rpy="0 0 0" xyz="-0.0519 0 -0.021003"/>
		<axis xyz="0 0 1"/>
		<limit effort="10" lower="-3.141592" upper="3.141592" velocity="1"/>
	</joint>

	<joint name="left_roll_joint" type="revolute">
		<parent link="left_yaw_link"/>
		<child link="left_roll_link"/>
		<origin rpy="0 0 0" xyz="0 0 -0.025916"/>
		<axis xyz="0 1 0"/>
		<limit effort="10" lower="-1.5707" upper="1.5707" velocity="1"/>
	</joint>
	<joint name="right_roll_joint" type="revolute">
		<parent link="right_yaw_link"/>
		<child link="right_roll_link"/>
		<origin rpy="0 0 0" xyz="0 0 -0.025916"/>
		<axis xyz="0 1 0"/>
		<limit effort="10" lower="-1.5707" upper="1.5707" velocity="1"/>
	</joint>
	<joint name="left_pitch_joint" type="revolute">
		<parent link="left_roll_link"/>
		<child link="left_pitch_link"/>
		<origin rpy="0 0 0" xyz="0 0 0"/>
		<axis xyz="1 0 0"/>
		<limit effort="10" lower="-0.349065" upper="2.617993333333333" velocity="1"/>
	</joint>	
	<joint name="right_pitch_joint" type="revolute">
		<parent link="right_roll_link"/>
		<child link="right_pitch_link"/>
		<origin rpy="0 0 0" xyz="0 0 0"/>
		<axis xyz="1 0 0"/>
		<limit effort="10" lower="-0.349065" upper="2.617993333333333" velocity="1"/>
	</joint>	
	<joint name="left_leg_joint" type="revolute">
		<parent link="left_pitch_link"/>
		<child link="left_leg_link"/>
		<origin rpy="0 0 0" xyz="0 0 -0.070405"/>
		<axis xyz="1 0 0"/>
		<limit effort="10" lower="-2.0420348" upper="2.0420348" velocity="1"/>
	</joint>	
	<joint name="right_leg_joint" type="revolute">
		<parent link="right_pitch_link"/>
		<child link="right_leg_link"/>
		<origin rpy="0 0 0" xyz="0 0 -0.070405"/>
		<axis xyz="1 0 0"/>
		<limit effort="10" lower="-2.0420348" upper="2.0420348" velocity="1"/>
	</joint>
	<joint name="left_leg_joint2" type="revolute">
		<parent link="left_leg_link"/>
		<child link="left_leg_link2"/>
		<origin rpy="0 0 0" xyz="0 0 -0.080865"/>
		<axis xyz="1 0 0"/>
		<limit effort="10" lower="-0.349065" upper="0.349065" velocity="1"/>
	</joint>
	<joint name="right_leg_joint2" type="revolute">
		<parent link="right_leg_link"/>
		<child link="right_leg_link2"/>
		<origin rpy="0 0 0" xyz="0 0 -0.080865"/>
		<axis xyz="1 0 0"/>
		<limit effort="10" lower="-0.349065" upper="0.349065" velocity="1"/>
	</joint>	
	<joint name="left_feet_joint" type="revolute">
		<parent link="left_leg_link2"/>
		<child link="left_feet_link"/>
		<origin rpy="0 0 0" xyz="0 0 0.0"/>
		<axis xyz="0 1 0"/>
		<limit effort="10" lower="-0.4188789333333333" upper="0.4188789333333333" velocity="1"/>
	</joint>
	<joint name="right_feet_joint" type="revolute">
		<parent link="right_leg_link2"/>
		<child link="right_feet_link"/>
		<origin rpy="0 0 0" xyz="0 0 0.0"/>
		<axis xyz="0 1 0"/>
		<limit effort="10" lower="-0.4188789333333333" upper="0.4188789333333333" velocity="1"/>
	</joint>					
</robot>


